Workbook

Sheet Scopus
A1: Authors | B1: Author(s) ID | C1: Title | D1: Year | E1: Source title | F1: Volume | G1: Issue | H1: Art. No. | I1: Page start | J1: Page end | K1: Page count | L1: Cited by | M1: DOI | N1: Link | O1: Affiliations | P1: Authors with affiliations | Q1: Abstract | R1: Author Keywords | S1: Index Keywords | T1: Correspondence Address | U1: Editors | V1: Publisher | W1: ISSN | X1: ISBN | Y1: CODEN | Z1: PubMed ID | AA1: Language of Original Document | AB1: Abbreviated Source Title | AC1: Document Type | AD1: Publication Stage | AE1: Access Type | AF1: Source | AG1: EID
A2: Ren H.; Wallhagen M.; Bahrami A.; Cehlin M. | B2: 58508037500; 36706721900; 57197657593; 12786288600 | C2: Life Cycle Impacts of Timber and Reinforced Concrete Floor Slabs: A Comparative Assessment | D2: 2025 | E2: Infrastructures | F2: 10 | G2: 12 | H2: 346 | L2: 0 | M2: 10.3390/infrastructures10120346 | N2: https://www.scopus.com/pages/publications/105025941668?origin=resultslist | O2: Department of Building Engineering, Energy Systems and Sustainability Science, Faculty of Engineering and Sustainable Development, University of Gävle, Gävle, 801 76, Sweden | P2: Ren H., Department of Building Engineering, Energy Systems and Sustainability Science, Faculty of Engineering and Sustainable Development, University of Gävle, Gävle, 801 76, Sweden; Wallhagen M., Department of Building Engineering, Energy Systems and Sustainability Science, Faculty of Engineering and Sustainable Development, University of Gävle, Gävle, 801 76, Sweden; Bahrami A., Department of Building Engineering, Energy Systems and Sustainability Science, Faculty of Engineering and Sustainable Development, University of Gävle, Gävle, 801 76, Sweden; Cehlin M., Department of Building Engineering, Energy Systems and Sustainability Science, Faculty of Engineering and Sustainable Development, University of Gävle, Gävle, 801 76, Sweden | Q2: Due to their sustainability, lightweight qualities, and simplicity of installation, wood slab systems have gained increasing attention in the building industry. Cross-laminated timber (CLT), an engineered wood product (EWP), improves structural strength and stability, offering a good alternative to conventional reinforced concrete (RC) slab systems. Conventional CLT, however, contains adhesives that pose environmental and end-of-life (EOL) disposal challenges. Adhesive-free CLT (AFCLT) panels have recently been introduced as a sustainable option, but their environmental performance has not yet been thoroughly investigated. In this study, the environmental impacts of five slab systems are evaluated and compared using the life cycle assessment (LCA) methodology. The investigated slab systems include a standard CLT slab (SCLT), three different AFCLT slabs (AFCLT1, AFCLT2, and AFCLT3), and an RC slab. The assessment considered abiotic depletion potential (ADP), global warming potential (GWP), ozone layer depletion potential (ODP), human toxicity potential (HTP), freshwater aquatic ecotoxicity potential (FAETP), marine aquatic ecotoxicity potential (MAETP), terrestrial ecotoxicity potential (TETP), photochemical oxidation potential (POCP), acidification potential (AP), and eutrophication potential (EP), covering the entire life cycle from production to disposal, excluding part of the use stage (B2-B7). The results highlight the advantages and drawbacks of each slab system, providing insights into selecting sustainable slab solutions. AFCLT2 exhibited the lowest environmental impacts across the assessed categories. On the contrary, the RC slab showed the highest environmental impact among the studied products. For example, the RC slab had the highest GWP of 67.422 kg CO2 eq, which was 1784.3% higher than that of AFCLT2 (3.779 kg CO2 eq). Additionally, the simulation displayed that the analysis results vary depending on the electricity source, which is influenced by geographical location. Using the Norwegian electricity mix resulted in the most sustainable outcomes compared with Sweden, Finland, and Saudi Arabia. This study contributes to the advancement of low-carbon construction techniques and the development of building materials with reduced environmental impacts in the construction sector. © 2025 by the authors. | R2: adhesive-free; cross-laminated timber; life cycle assessment; slab; sustainability | T2: H. Ren; Department of Building Engineering, Energy Systems and Sustainability Science, Faculty of Engineering and Sustainable Development, University of Gävle, Gävle, 801 76, Sweden; email: ren.honghao@hig.se | V2: Multidisciplinary Digital Publishing Institute (MDPI) | W2: 24123811 | AA2: English | AB2: Infrastructures | AC2: Article | AD2: Final | AE2: All Open Access; Gold Open Access; Green Open Access | AF2: Scopus | AG2: 2-s2.0-105025941668
A3: Becker I.; Anderson F.; Phillips A.R. | B3: 58315871900; 58315621200; 56642281000 | C3: Structural design of hybrid steel-timber buildings for lower production stage embodied carbon emissions | D3: 2023 | E3: Journal of Building Engineering | F3: 76 | H3: 107053 | L3: 17 | M3: 10.1016/j.jobe.2023.107053 | N3: https://www.scopus.com/pages/publications/85161998408?origin=resultslist | O3: Department of Civil & Environmental Engineering, Washington State University, Pullman, 99163, WA, United States | P3: Becker I., Department of Civil & Environmental Engineering, Washington State University, Pullman, 99163, WA, United States; Anderson F., Department of Civil & Environmental Engineering, Washington State University, Pullman, 99163, WA, United States; Phillips A.R., Department of Civil & Environmental Engineering, Washington State University, Pullman, 99163, WA, United States | Q3: Using cross laminated timber (CLT) floor panels in combination with steel framing has been identified as a promising new structural configuration that can reduce the embodied greenhouse gas emissions of buildings. This project evaluated efficient structural design of hybrid steel-timber floor sections for a wide range of design parameters to determine the reductions in global warming potential possible relative to a conventional steel-concrete cross section. Each of the structural designs was checked for strength limit states, deflection, and minimum fire rating of either unrated, 1-h, or 2-h for a range of deck spans between 2.3 m and 4.6 m and beam spans between 5.5 m and 13.5 m. For an unrated floor assembly there is little global warming potential benefit to use steel-timber floors if a topping slab is included on top of the CLT slab. Whereas, using steel-timber configurations without a topping slab result in the largest global warming potential reductions. For the 1-h and 2-h ratings, even steel-timber configurations with a 64 mm thick topping slab had up to 20% reduction in global warming potential compared to the steel-concrete alternative. Additionally, several considerations that can drastically affect the global warming potential results were discussed. The results from this project demonstrate the best practices for structural design of hybrid steel-timber buildings to reduce global warming potential of the superstructure frame by between 5% and 35% relative to conventional steel and concrete construction. © 2023 Elsevier Ltd | S3: Architectural design; Carbon; Concretes; Floors; Gas emissions; Global warming; Greenhouse gases; Timber; % reductions; Conventional steel; Cross laminated; Embodied carbons; Global warming potential; Laminated timber; Production stage; Steel concrete; Timber buildings; Timber floors; Structural design | T3: A.R. Phillips; Department of Civil & Environmental Engineering, Washington State University, Pullman, 99163, United States; email: a.phillips@wsu.edu | V3: Elsevier Ltd | W3: 23527102 | AA3: English | AB3: J. Build. Eng. | AC3: Article | AD3: Final | AF3: Scopus | AG3: 2-s2.0-85161998408
A4: Salles E Portugal R.; Lawrence B.; Laleicke P.F.; Sinha A. | B4: 57203041069; 57203043062; 57201461333; 57203184231 | C4: Technical note: A preliminary study to quantify the environmental impacts of concrete and cork flooring | D4: 2018 | E4: Wood and Fiber Science | F4: 50 | G4: 1 | I4: 104 | J4: 112 | K4: =scopus[[#This Row],[Page end]]-scopus[[#This Row],[Page start]] -> 8 | L4: 8 | M4: 10.22382/wfs-2018-011 | N4: https://www.scopus.com/pages/publications/85050349907?origin=resultslist | O4: Department of Forest Biomaterials, North Carolina State University, Raleigh, 27695, NC, United States; Department of Wood Science and Engineering, Oregon State University, Corvallis, 97331, OR, United States | P4: Salles E Portugal R., Department of Forest Biomaterials, North Carolina State University, Raleigh, 27695, NC, United States; Lawrence B., Department of Forest Biomaterials, North Carolina State University, Raleigh, 27695, NC, United States; Laleicke P.F., Department of Forest Biomaterials, North Carolina State University, Raleigh, 27695, NC, United States; Sinha A., Department of Wood Science and Engineering, Oregon State University, Corvallis, 97331, OR, United States | Q4: Cross-laminated timber (CLT) is currently sought as a sustainable and green building material. It does not meet the International Building Code sound insulating requirements, and either a concrete slab or hardwood flooring is needed to meet the acoustic and vibrational performance benchmark. Cork, the bark of the cork oak, is well known for its sound insulating properties and often used for flooring applications in Europe. The cork-based flooring system is a potential solution to the acoustic problem faced by the CLT building industry. The goal of this preliminary study was to quantify the environmental impacts of a concrete and a cork-based flooring system that includes CLT. A life-cycle analysis (LCA) is conducted to focus on a cradle-to-gate comparison of a cork flooring system with a locally sourced concrete flooring system for use in a proposed CLT structure in Portland, OR. The LCA reveals that the global warming potential (GWP) of concrete is 25% higher for the concrete flooring system. For cork flooring, the GWP is mainly driven by inorganic compounds in the flooring assembly. The main source for cork is Portugal, which increases the GWP of the cork flooring system, in contrast to that of concrete flooring, which typically has a regional production and supply system. As environmental abatement costs increase, the profitability of cork flooring can increase to justify the creation of an appropriate system to close the loop. © 2018 by the Society of Wood Science and Technology. | R4: Cement; CLT; Cork; Flooring; LCA; Renewable; Sustainable | S4: Cork; Floors; Hardwoods; Inorganic Compounds; International; Life Cycle; Acoustic fields; Artificial life; Benchmarking; Building codes; Cements; Concrete construction; Concrete slabs; Construction industry; Environmental impact; Global warming; Hardwoods; Inorganic compounds; Life cycle; Sustainable development; Cork; Environmental abatement costs; Flooring; Global warming potential; Green building materials; International Building Code; Renewable; Sustainable; Floors | T4: P.F. Laleicke; Department of Forest Biomaterials, North Carolina State University, Raleigh, 27695, United States; email: Frederik@Laleicke.com | V4: Society of Wood Science and Technology | W4: 7356161 | Y4: WFSCD | AA4: English | AB4: Wood Fiber Sci | AC4: Article | AD4: Final | AE4: All Open Access; Gold Open Access | AF4: Scopus | AG4: 2-s2.0-85050349907
A5: Eslami H.; Yaghma A.; Jayasinghe L.B.; Waldmann D. | B5: 57272842800; 58604635500; 55626539700; 26636742700 | C5: INFLUENCE OF DIFFERENT END-OF-LIFE CYCLE SCENARIOS ON THE ENVIRONMENTAL IMPACTS OF TIMBER-CONCRETE COMPOSITE FLOOR SYSTEMS | D5: 2023 | E5: 13th World Conference on Timber Engineering, WCTE 2023 | F5: 2 | I5: 982 | J5: 988 | K5: =scopus[[#This Row],[Page end]]-scopus[[#This Row],[Page start]] -> 6 | L5: 10 | M5: 10.52202/069179-0134 | N5: https://www.scopus.com/pages/publications/85166200336?origin=resultslist | O5: FSTM University of Luxembourg, Luxembourg; Massivbau TU Darmstadt, Germany | P5: Eslami H., FSTM University of Luxembourg, Luxembourg; Yaghma A., FSTM University of Luxembourg, Luxembourg; Jayasinghe L.B., FSTM University of Luxembourg, Luxembourg; Waldmann D., Massivbau TU Darmstadt, Germany | Q5: Timber-concrete composite (TCC) floor systems attracted attention in the construction industry because of their low environmental impacts while demonstrating decent load-bearing capacity. However, the environmental impacts of possible end-of-life scenarios of TCC floors have not been extensively studied. To address this gap, a comprehensive life cycle assessment (LCA) study was conducted on three different slabs: a Reinforced concrete slab, a Steel concrete composite slab, and a CLT-concrete composite slab. The study revealed that the CLT-concrete composite slab has the lowest Global Warming Potential (GWP) among the three slabs. Subsequently, a more detailed LCA is performed on the CLT-concrete composite slab considering three different end-of-life scenarios of the CLT: 1. Energy recovery via incineration, 2. The prevailing scenario in Europe (a combination of energy recovery, recycling, and disposal), and 3. Reuse. The results show all three scenarios are beneficial in terms of GWP whereas the 3rd scenario is the most beneficial one. © (2023) WORLD CONFERENCE ON TIMBER ENGINEERING 2023 (WCTE 2023) All rights reserved. | R5: Environmental impact; Life cycle assessment; Reusable slab; Timber-concrete composite floor system | S5: Concrete slabs; Construction industry; Environmental impact; Floors; Forestry; Global warming; Reinforced concrete; Timber; Composite floor systems; Composite slab; Concrete composites; End of lives; Energy recovery; Global warming potential; Life cycle assessment; Reusable slab; Timber-concrete composite floor system; Timber-concrete composites; Life cycle | U5: Nyrud A.Q.; Malo K.A.; Nore K.; Alsen K.W.L.; Tulebekova S.; Staehr E.R.; Bergh G.; Wuyts W. | V5: World Conference on Timber Engineering (WCTE) | X5: 978-171387329-7 | AA5: English | AB5: World Conf. Timber Eng., WCTE | AC5: Conference paper | AD5: Final | AE5: All Open Access; Gold Open Access | AF5: Scopus | AG5: 2-s2.0-85166200336
A6: Hassan O.A.B.; Öberg F.; Gezelius E. | B6: 14022549700; 59429427900; 57210149692 | C6: Cross-laminated timber flooring and concrete slab flooring: A comparative study of structural design, economic and environmental consequences | D6: 2019 | E6: Journal of Building Engineering | F6: 26 | H6: 100881 | L6: 55 | M6: 10.1016/j.jobe.2019.100881 | N6: https://www.scopus.com/pages/publications/85069640267?origin=resultslist | O6: Department of Science and Technology, Linköping University, Norrköping, 601 74, Sweden; Drivhusvägen 38, Huskvarna, 56139, Sweden; Värmbolsvägen 3, Katrineholm, 641 51, Sweden | P6: Hassan O.A.B., Department of Science and Technology, Linköping University, Norrköping, 601 74, Sweden; Öberg F., Drivhusvägen 38, Huskvarna, 56139, Sweden; Gezelius E., Värmbolsvägen 3, Katrineholm, 641 51, Sweden | Q6: This paper compares cross-laminated timber (CLT) flooring and concrete slab flooring with respect to structural design, cost analysis, and greenhouse gas emissions. The effect of floor span on design values, costs, and carbon dioxide emissions is analysed in terms of structural design, economy, and environmental impact. Different cross-sections are chosen for this purpose. The study shows that CLT flooring has significantly lower emissions of climate-impact greenhouse gases, and its ability to store carbon is significantly greater than the capacity of concrete storage. From an economic point of view, the CLT material is more expensive than concrete. However, the estimated “ready-to-assemble” cost of both floor types is quite similar. The study shows that CLT flooring can compete with a concrete slab floor when it comes to a span as wide as 7 m without violating the structural requirements. However, with an increase in span, it is more difficult to meet the requirements for vibration for a CLT floor than for a concrete slab. At shorter spans, the moment capacity is often a decisive factor for concrete slabs while deformation is the decisive factor for a CLT floor. For larger spans, resonance frequency and deformation are crucial for the CLT floor, while the long-term deformation of the concrete is the decisive factor in structural design. © 2019 Elsevier Ltd | R6: Cost analysis; Eurocode 2; Eurocode 3; Greenhouse effects; Timber and concrete slabs | S6: Carbon dioxide; Codes (standards); Concrete slabs; Cost accounting; Cost benefit analysis; Deformation; Environmental impact; Finite difference method; Floors; Gas emissions; Global warming; Greenhouse effect; Greenhouse gases; Laminating; Structural design; Comparatives studies; Cost analysis; Cross laminated; Economic consequences; Environmental consequences; Eurocode 3; Eurocode2; Laminated timber; Timber and concrete slab; Timber floors; Timber | T6: O.A.B. Hassan; Department of Science and Technology, Linköping University, Norrköping, 601 74, Sweden; email: osama.hassan@liu.se | V6: Elsevier Ltd | W6: 23527102 | AA6: English | AB6: J. Build. Eng. | AC6: Review | AD6: Final | AF6: Scopus | AG6: 2-s2.0-85069640267
A7: Rauf A.; Shafiq M.T. | B7: 56592043300; 55671258600 | C7: Reducing Embodied Energy of Floor Assembly: A Case for Using CLT in Mid-Rise Residential Buildings | D7: 2024 | E7: Lecture Notes in Civil Engineering | F7: 389 | I7: 157 | J7: 163 | K7: =scopus[[#This Row],[Page end]]-scopus[[#This Row],[Page start]] -> 6 | L7: 2 | M7: 10.1007/978-981-99-6368-3_14 | N7: https://www.scopus.com/pages/publications/85185826337?origin=resultslist | O7: Department of Architectural Engineering, College of Engineering, United Arab Emirates University, Al Ain, Abu Dhabi, 15551, United Arab Emirates | P7: Rauf A., Department of Architectural Engineering, College of Engineering, United Arab Emirates University, Al Ain, Abu Dhabi, 15551, United Arab Emirates; Shafiq M.T., Department of Architectural Engineering, College of Engineering, United Arab Emirates University, Al Ain, Abu Dhabi, 15551, United Arab Emirates | Q7: Buildings’ energy consumption is estimated between 30 and 40% of its global use, resulting in various environmental impacts. There is a need to reduce the energy consumption by buildings in the construction phase, along with the operation phase, which is well-studied. Concrete is a construction material that is being used widely in the construction industry but has high embodied energy. In the move towards using low-energy materials, new materials and construction technologies are being developed and studied. In this regard, Cross lamented timber (CLT) can be a sustainable alternative due to its excellent load-carrying capabilities, and therefore has become an emerging choice in buildings as a low embodied energy material alternative. This paper aims to explore the potential initial embodied energy reduction benefits by comparing the initial embodied energy consumption of concrete floor systems and CLT floor systems for mid-rise residential buildings. An eight-story apartment building was used for this analysis. This study shows that replacing the reinforced concrete floor with a CLT floor results in more than four times reduction in embodied energy associated with floor construction. This demonstrates the need for careful selection of materials in buildings at the design stage to reduce their embodied energy and consider the use of CLT instead of reinforced concrete in this context. Results from this initial study also indicate the need for more studies to address the challenges associated with the adoption of this low embodied energy material. © The Author(s), under exclusive license to Springer Nature Singapore Pte Ltd. 2024. | R7: Construction materials; Cross-laminated timber; Floor assembly; Initial embodied energy; Input–output based hybrid assessment | S7: Apartment houses; Construction industry; Energy utilization; Environmental impact; Hybrid materials; Reinforced concrete; Timber; Cross laminated; Cross-laminated timber; Embodied energy; Energy materials; Floor assembly; Initial embodied energy; Input-output; Input–output based hybrid assessment; Laminated timber; Residential building; Floors | T7: A. Rauf; Department of Architectural Engineering, College of Engineering, United Arab Emirates University, Abu Dhabi, Al Ain, 15551, United Arab Emirates; email: a.rauf@uaeu.ac.ae | U7: Casini M. | V7: Springer Science and Business Media Deutschland GmbH | W7: 23662557 | X7: 978-981996367-6 | AA7: English | AB7: Lect. Notes Civ. Eng. | AC7: Conference paper | AD7: Final | AF7: Scopus | AG7: 2-s2.0-85185826337
A8: Chiniforush A.A.; Akbarnezhad A.; Valipour H.; Dackermann U. | B8: 57190258599; 36730725400; 6508258428; 29667491700 | C8: Dynamic response of steel-timber composite (STC) beams | D8: 2017 | E8: 24th International Congress on Sound and Vibration, ICSV 2017 | L8: 14 | N8: https://www.scopus.com/pages/publications/85029448417?origin=resultslist | O8: Centre for Infrastructure Engineering and Safety, School of Civil and Environmental Engineering, University of New South Wales, Sydney, NSW, Australia | P8: Chiniforush A.A., Centre for Infrastructure Engineering and Safety, School of Civil and Environmental Engineering, University of New South Wales, Sydney, NSW, Australia; Akbarnezhad A., Centre for Infrastructure Engineering and Safety, School of Civil and Environmental Engineering, University of New South Wales, Sydney, NSW, Australia; Valipour H., Centre for Infrastructure Engineering and Safety, School of Civil and Environmental Engineering, University of New South Wales, Sydney, NSW, Australia; Dackermann U., Centre for Infrastructure Engineering and Safety, School of Civil and Environmental Engineering, University of New South Wales, Sydney, NSW, Australia | Q8: Due to their recyclability and considerably lower embodied carbon, timber floors are advocated extensively as a more sustainable alternative to concrete slabs. Cross-Laminated Timber (CLT) is an engineered wood product with low variability in mechanical properties and therefore of high reliability and quality, presenting a very attractive alternative to concrete slabs. Replacing the reinforced concrete slabs in conventional steel-concrete composite with an engineered timber product (such as CLT) leads to a significant reduction in the overall weight of the floors, and consequently the weight of supporting structural elements including columns and beams. The combination of light CLT panels and steel may allow an increase in the load-carrying span of the floor systems which is highly desirable from an architectural viewpoint. However, one major drawback negatively affecting the serviceability and thus widespread adoption of such systems in practice is the high susceptibility of undesirable vibration in steel-timber composite (STC) floors under service load conditions due to low mass and damping ratio of timber slabs. This paper presents the results of a series of experimental impact hammer tests conducted to investigate the vibrational characteristics of different STC beams. Three STC beams with different shear connector types are experimentally tested to extract their natural frequencies. Numerical models are generated and validated using the results of previously performed short-term failure tests. The validated numerical models are then used to extract the linear flexural stiffness of STC beams to determine the deflection of the beams under self-weight. The experimental results are compared against results from analytical models calculating the fundamental natural frequencies of the beams. Further, the obtained dynamic indices of STC beams are evaluated based on available standard regulations. | R8: Cross laminated timber (CLT); Impact hammer testing; Steel-timber composite (STC) beams; Vibration serviceability of floors | S8: Building materials; Carbon; Composite structures; Concrete slabs; Concretes; Floors; Hammers; Laminated composites; Laminating; Natural frequencies; Numerical models; Reinforced concrete; Steel testing; Wood products; Architectural viewpoints; Cross laminated; Engineered wood products; Impact hammer testing; Impact hammer tests; Service load condition; Short-term failures; Vibration serviceability; Timber | U8: Gibbs B. | V8: International Institute of Acoustics and Vibration, IIAV | AA8: English | AB8: Int. Congr. Sound Vib., ICSV | AC8: Conference paper | AD8: Final | AF8: Scopus | AG8: 2-s2.0-85029448417
A9: Mirdad M.A.H.; Daneshvar H.; Joyce T.; Chui Y.H. | B9: 57190062072; 36730729900; 57204966326; 7004982369 | C9: Sustainability Design Considerations for Timber-Concrete Composite Floor Systems | D9: 2021 | E9: Advances in Civil Engineering | F9: 2021 | H9: 6688076 | L9: 21 | M9: 10.1155/2021/6688076 | N9: https://www.scopus.com/pages/publications/85103552039?origin=resultslist | O9: Department of Civil and Environmental Engineering, University of Alberta, 9211 116 Street NW, Edmonton, T6G1H9, AB, Canada | P9: Mirdad M.A.H., Department of Civil and Environmental Engineering, University of Alberta, 9211 116 Street NW, Edmonton, T6G1H9, AB, Canada; Daneshvar H., Department of Civil and Environmental Engineering, University of Alberta, 9211 116 Street NW, Edmonton, T6G1H9, AB, Canada; Joyce T., Department of Civil and Environmental Engineering, University of Alberta, 9211 116 Street NW, Edmonton, T6G1H9, AB, Canada; Chui Y.H., Department of Civil and Environmental Engineering, University of Alberta, 9211 116 Street NW, Edmonton, T6G1H9, AB, Canada | Q9: Over the last few decades, there has been growing interest in the use of low-carbon materials to reduce the environmental impacts of the construction industry. The advent of mass timber panels (MTP), such as cross laminated timber (CLT), has allowed structural engineers to specify a low-carbon material for a variety of floor design considerations. However, serviceability issues such as vibration and deflection are limiting the construction of longer span timber-only floor systems and have encouraged the development of timber-concrete composite (TCC) systems. The use of concrete would negatively impact on the carbon footprint of the TCC floor system and should be minimized. The purpose of this study was to study the impact on embodied carbon in the TCC system, when the ratio of timber and concrete was varied for specific floor spans. Two MTP products were considered, CLT and glued laminated timber (GLT). The floors were designed to satisfy structural, acoustic, and vibration criteria, and the results were presented in the form of span tables. It was found that using thicker MTP instead of adding concrete thickness to meet a specific span requirement can lead to lower embodied carbon values. Increasing concrete thickness for long-span floor systems led to a reduction in allowable floor span due to the vibration criterion being the controlling design parameter. Increasing timber thickness also resulted in higher strength and stiffness to weight ratios, which would contribute toward reducing the size of lateral load resisting systems and foundations, resulting in further reductions in the embodied carbon of the entire structure. © 2021 Md Abdul Hamid Mirdad et al. | T9: M.A.H. Mirdad; Department of Civil and Environmental Engineering, University of Alberta, Edmonton, 9211 116 Street NW, T6G1H9, Canada; email: mdabdul@ualberta.ca; M.A.H. Mirdad; Department of Civil and Environmental Engineering, University of Alberta, Edmonton, 9211 116 Street NW, T6G1H9, Canada; email: mdabdul@ualberta.ca | V9: Hindawi Limited | W9: 16878086 | AA9: English | AB9: Adv. Civ. Eng. | AC9: Article | AD9: Final | AE9: All Open Access; Gold Open Access; Green Open Access | AF9: Scopus | AG9: 2-s2.0-85103552039
A10: Ijeoma M.W.; Ou S.; Nabati A.; Chen H.; Stoner M.; Layton P.; Albright D.; Ross B.; Pang W.; Carbajales-Dale M. | B10: 58644049100; 58577750400; 36601248800; 58643831700; 57193124992; 6602579104; 57193121876; 16547000500; 24315073800; 56703480100 | C10: Environmental benefits of using an all-wood floor system in midrise office construction: an LCA based comparative case study in the Southeastern United States | D10: 2025 | E10: Environmental Research Communications | F10: 7 | G10: 11 | H10: 115024 | L10: 0 | M10: 10.1088/2515-7620/ae1f6a | N10: https://www.scopus.com/pages/publications/105034173755?origin=resultslist | O10: School of Civil and Environmental Engineering and Earth Sciences, Clemson University, United States; Wood Utilization + Design Institute, Clemson University, United States; School of Architecture, Clemson University, United States | P10: Ijeoma M.W., School of Civil and Environmental Engineering and Earth Sciences, Clemson University, United States; Ou S., School of Civil and Environmental Engineering and Earth Sciences, Clemson University, United States; Nabati A., School of Civil and Environmental Engineering and Earth Sciences, Clemson University, United States; Chen H., School of Civil and Environmental Engineering and Earth Sciences, Clemson University, United States; Stoner M., School of Civil and Environmental Engineering and Earth Sciences, Clemson University, United States; Layton P., Wood Utilization + Design Institute, Clemson University, United States; Albright D., School of Architecture, Clemson University, United States; Ross B., School of Civil and Environmental Engineering and Earth Sciences, Clemson University, United States; Pang W., School of Civil and Environmental Engineering and Earth Sciences, Clemson University, United States; Carbajales-Dale M., School of Civil and Environmental Engineering and Earth Sciences, Clemson University, United States | Q10: This study presents a cradle-to-grave whole-building life cycle assessment (WBLCA) of two functionally equivalent mid-rise commercial office buildings in Atlanta, Georgia: one constructed using mass timber with an all-wood composite floor system (CLT and GLT), and the other using conventional steel and reinforced concrete. Using Tally®, a Revit-integrated LCA tool, environmental impacts were evaluated across eight categories: global warming, acidification, eutrophication, smog formation, ozone depletion, total primary energy, renewable and non-renewable energy use, and normalized to 1 m2 of floor area over a 50-year service life. Results showed that the mass timber building required 25% less material mass and achieved a 4.5% reduction in global warming potential (GWP) (2801.12 kg CO2-eq/m2 versus 2975.85 kg CO2-eq/m2 for the steel–concrete system) and 27.9% more renewable energy use. However, timber’s carbon advantage was diminished by conservative end-of-life modeling, assuming 63.5% wood landfilling and 98% steel recycling, which significantly influenced net GWP through Module D credits. Additionally, the mass timber building stored 857,551 tCO2-eq in wood components (long-term biogenic carbon storage). The timber structure also exhibited higher eutrophication and acidification impacts, primarily due to emissions from adhesives and chemical treatments. Contribution analysis showed that finishes and non-structural components contributed disproportionately to overall impacts in both systems, illustrating the limitations of focusing solely on structural materials in building LCA. The findings emphasize the need for integrated material strategies, circular end-of-life planning, and regionally grounded modeling to fully realize the environmental potential of wood-based construction. © 2025 The Author(s). Published by IOP Publishing Ltd. | R10: biogenic carbon; cross laminated timber; mid-rise office buildings; U.S. Southeast; whole building life cycle assessment; wood composite floor system | S10: United States; building; carbon; comparative study; composite; construction; floor; life cycle analysis; timber; wood | T10: M.W. Ijeoma; School of Civil and Environmental Engineering and Earth Sciences, Clemson University, United States; email: mijeoma@clemson.edu | V10: Institute of Physics | W10: 25157620 | AA10: English | AB10: Environ. Res. Commun. | AC10: Article | AD10: Final | AE10: All Open Access; Gold Open Access; Green Open Access | AF10: Scopus | AG10: 2-s2.0-105034173755
A11: Cleghorn S.; Callaghan A. | B11: 59984081900; 58591306600 | C11: BALANCING FASTENER SPACING, ACOUSTICS, AND SPAN LENGTH IN EXPOSED CLT FLOOR-CEILING ASSEMBLIES | D11: 2025 | E11: Proceedings from the 14th World Conference on Timber Engineering: Advancing Timber for the Future Built Environment, WCTE 2025 | I11: 1416 | J11: 1422 | K11: =scopus[[#This Row],[Page end]]-scopus[[#This Row],[Page start]] -> 6 | L11: 0 | M11: 10.52202/080513-0173 | N11: https://www.scopus.com/pages/publications/105010279515?origin=resultslist | O11: Pliteq Inc., Toronto, Canada; Pliteq Inc., Vancouver, Canada | P11: Cleghorn S., Pliteq Inc., Toronto, Canada; Callaghan A., Pliteq Inc., Vancouver, Canada | Q11: Aside from sustainability, one of the most unique benefits of mass timber as a construction material is its extremely high strength-to-weight ratio. As a result, the weight of a floor slab in a mass timber building is much lighter than in a building constructed with conventional material. This unique benefit of engineered timber also comes with unique challenges. Albeit ironic, the low mass in mass timber assemblies is to blame for two of the most prominent pain points in engineered timber construction: floor vibration and sound transmission. Limits on floor vibration often result in short span lengths and tight structural grid spacing. Timber-concrete composite (TCC) floor systems are one method that can be used to alleviate this restriction. However, connecting a concrete topping to the timber panel underneath with mechanical fasteners harms the acoustic performance of the floor assembly. In this paper, the relationship between fastener spacing, composite slab behaviour, and sound transmission is investigated. Physical testing is carried out to determine the degree of composite action achieved with a timber-concrete composite system in the presence of a resilient acoustic interlayer. The data obtained is used to analyse the resulting span and acoustic performance with various spacing of fasteners. © (2025) WORLD CONFERENCE ON TIMBER ENGINEERING 2025 (WCTE 2025) All rights reserved. | R11: Acoustics; Cross Laminated Timber; Span; Vibration | S11: Acoustic wave transmission; Architectural acoustics; Concrete slabs; Fasteners; Structural dynamics; Timber; Transmissions; Wooden buildings; Wooden construction; Acoustic performance; Cross laminated; Cross laminated timber; Floor vibrations; Laminated timber; Sound transmission; Span; Span length; Timber-concrete composites; Vibration; Floors | U11: Rischmiller K.; Saleem M.A.; Downey C.; Gattas J.; Hossy D.; Ottenhaus L.; Wu W.; Zhang Y.; Yan Z. | V11: World Conference on Timber Engineering (WCTE) | X11: 979-833132089-8 | AA11: English | AB11: Proc. from World Conf. Timber Eng.: Adv. Timber Future Built Environ., WCTE | AC11: Conference paper | AD11: Final | AF11: Scopus | AG11: 2-s2.0-105010279515
A12: Park J.H.; Yuk H.; Kang S.T.; Kim S. | B12: 32867930500; 57219846158; 59722442600; 8542733000 | C12: Integrating thermal bridge analysis with life-cycle assessment: energy and environmental performance of Ply-Lam CLT envelopes in ZEB-Level apartments | D12: 2026 | E12: Building and Environment | F12: 290 | H12: 114169 | L12: 0 | M12: 10.1016/j.buildenv.2025.114169 | N12: https://www.scopus.com/pages/publications/105026165786?origin=resultslist | O12: Department of Architecture and Architectural Engineering, Yonsei University, Seoul, 03722, South Korea | P12: Park J.H., Department of Architecture and Architectural Engineering, Yonsei University, Seoul, 03722, South Korea; Yuk H., Department of Architecture and Architectural Engineering, Yonsei University, Seoul, 03722, South Korea; Kang S.T., Department of Architecture and Architectural Engineering, Yonsei University, Seoul, 03722, South Korea; Kim S., Department of Architecture and Architectural Engineering, Yonsei University, Seoul, 03722, South Korea | Q12: Building envelopes play a decisive role in both the operational energy use and life-cycle carbon emissions, particularly when junction thermal bridges are considered. In Korean apartment housing, reinforced concrete (RC) construction with interior insulation remains dominant; however, it is structurally vulnerable to heat losses at wall–slab connections. To address this drawback, ply-lam cross-laminated timber (CLT) was evaluated as an alternative envelope system using a coupled framework integrating ISO 10,211-based thermal bridge modeling, whole-building simulations in DesignBuilder, and life-cycle assessment (LCA), following EN 15,804+A2. Substituting RC walls with ply-lam CLT reduced annual primary energy consumption by 5%–9%. Junction thermal bridges in RC resulted in additional losses of 125.1 W/K, whereas the CLT alternative achieved only 13.0 W/K, representing an 89.6% reduction. Roof and corner junctions in CLT satisfied the stringent Ψ ≤ 0.05 W/m·K benchmark, whereas floor junctions approached this target. From a carbon perspective, CLT envelopes achieved an approximately 10% reduction in 30-year operational global warming potential (GWP) and further reductions in embodied GWP through lower manufacturing emissions and biogenic carbon storage, leading to a net decrease of approximately 59 kgCO₂eq/m² relative to RC. The results highlight the structural vulnerability of RC systems and the resilience of CLT alternatives when configured with continuous insulation and optimized details. By integrating junction-scale thermal bridge modeling with whole-building energy and life-cycle carbon analyses, this study provides comprehensive evidence for CLT as a competitive pathway to support low-carbon housing and national carbon neutrality goals. © 2025 | R12: Apartment; Cross-laminated timber; Life-cycle assessment; Thermal bridge; Zero-energy building | S12: Bridges; Carbon; Carbon cycle; Concrete slabs; Energy utilization; Intelligent buildings; Laminating; Life cycle; Life cycle assessment; Structural design; Walls (structural partitions); Zero energy buildings; % reductions; Apartment; Bridge analysis; Bridge model; Cross laminated; Cross-laminated timber; Global warming potential; Laminated timber; Thermal bridge; Zero energies; carbon emission; energy management; energy use; environmental assessment; life cycle analysis; Apartment houses | T12: S. Kim; Department of Architecture and Architectural Engineering, Yonsei University, Seoul, 03722, South Korea; email: kimsumin@yonsei.ac.kr | V12: Elsevier Ltd | W12: 3601323 | Y12: BUEND | AA12: English | AB12: Build. Environ. | AC12: Article | AD12: Final | AF12: Scopus | AG12: 2-s2.0-105026165786
A13: Sener K.; Mutlu E.; Anil O. | B13: 55366144500; 57215544445; 6508251680 | C13: A COMPARATIVE DESIGN AND LCA STUDY ON THE FEASIBILITY OF EARTHQUAKE-RESISTANT MASS-TIMBER BUILDINGS | D13: 2024 | E13: World Conference on Earthquake Engineering proceedings | F13: 2024 | L13: 0 | N13: https://www.scopus.com/pages/publications/105027857079?origin=resultslist | O13: Auburn University, Auburn, AL, United States; Gazi University, Ankara, Turkey | P13: Sener K., Auburn University, Auburn, AL, United States; Mutlu E., Auburn University, Auburn, AL, United States; Anil O., Gazi University, Ankara, Turkey | Q13: The building and construction industry drives the largest portion of global energy use and emissions. With climate change mitigation being a forefront topic of concern, the building and construction industry has a responsibility to alleviate its environmental impact, particularly in developing countries with a need for sustainable structural systems that explicitly consider environmental impact. Mass timber has recently emerged as a viable alternative to conventional construction materials and gained significant popularity in many developed nations. Recent design code advancements on mass timber elements and systems have paved the way for their use as multi-story building systems in seismic-prone regions. The devastating earthquakes that took place on February 3, 2023, in Turkiye have showcased the poor performance of the reinforced concrete building inventory. As the earthquakes affected a populated province where a vast majority of buildings sustained significant damage, hundreds of thousands of new buildings are expected to be constructed in the near term. Considering 93% of Turkiye’s population resides in considerably high earthquake-hazard regions, this rebuilding process gives a rare opportunity for constructing buildings with low-carbon structural solutions that utilize sustainable materials as well as modularity and prefabrication practices, therefore enabling the speedy constructability needed for the region. To evaluate the feasibility and potential benefits of seismic-resistant multi-story mass timber structures in Turkiye, this study conducts a comparative study between functionally equivalent reinforced concrete and mass timber buildings. The buildings use generic floor plans obtained from governmental agencies in Turkiye that mainly utilize shear wall systems for both gravity and lateral load resistance. The objective of the study was to investigate the design, lateral load performance, and economic aspects of the systems with a particular emphasis on sustainability through conducting a comparative life cycle assessment of mass timber relative to conventional reinforced concrete systems using realistic building layouts. The designed timber structure showcased adequate performance under seismic loads and was found to be considerably more environmentally advantageous compared to the companion reinforced concrete building. The mass-timber building resulted being more expensive based on material cost, but the difference is expected to shrink with more widespread CLT manufacturing in future. © 2024, International Association for Earthquake Engineering. All rights reserved. | S13: Concrete buildings; Concrete construction; Earthquake effects; Mortar; Seismic design; Structural dynamics; Wooden buildings; Building and construction; Climate change mitigation; Earthquake resistant; Energy emissions; Energy use; Global energy; Lateral loads; Reinforced concrete buildings; Timber buildings; Timber structures; Shear walls | V13: International Association for Earthquake Engineering | W13: 30065933 | AA13: English | AB13: World Conf. Earthq. Eng. Proc. | AC13: Book chapter | AD13: Final | AF13: Scopus | AG13: 2-s2.0-105027857079
A14: Lolli N.; Fufa S.M.; Kjendseth Wiik M. | B14: 56395455700; 49863337000; 57913703100 | C14: An assessment of greenhouse gas emissions from CLT and glulam in two residential nearly zero energy buildings | D14: 2019 | E14: Wood Material Science and Engineering | F14: 14 | G14: 5 | I14: 342 | J14: 354 | K14: =scopus[[#This Row],[Page end]]-scopus[[#This Row],[Page start]] -> 12 | L14: 33 | M14: 10.1080/17480272.2019.1655792 | N14: https://www.scopus.com/pages/publications/85070950776?origin=resultslist | O14: SINTEF, Building and Infrastructure, Trondheim, Norway; SINTEF, Building and Infrastructure, Oslo, Norway | P14: Lolli N., SINTEF, Building and Infrastructure, Trondheim, Norway; Fufa S.M., SINTEF, Building and Infrastructure, Oslo, Norway; Kjendseth Wiik M., SINTEF, Building and Infrastructure, Oslo, Norway | Q14: This paper analyses and compares the embodied and operational greenhouse gas (GHG) emissions of two nearly Zero Energy Buildings, a student housing building in Trondheim, Norway, and a residential building in Växjö, Sweden. The student housing in Trondheim, Moholt Allmenning Tower B, is a 9-storey tower composed of cross laminated timber (CLT) panels and concrete floor slabs with a total heated floor area of 3801 m2. The apartment building in Växjö, House A, consists of 8 floors composed of glued laminated timber (glulam) beams with a wood-cassette floor, and concrete slabs with a total heated floor area of 3483 m2. The results show that the use of CLT has the largest reduction of total GHG emissions due to substituting concrete elements in the structural frame. The comparative assessment of the external wall and the internal floor constructions shows that the use of CLT adds marginal GHG emissions per unit of area of component. The calculation of operational GHG emissions shows that the use of the Nordic electricity mix disfavours the full-electric energy system of Moholt Allmenning Tower B, in contrast to the district heating used in Norra Vallen Building A. © 2019, © 2019 Informa UK Limited, trading as Taylor & Francis Group. | R14: Cross laminated timber; environmental product declaration; glue laminated timber; greenhouse gas emission; life cycle assessment; nearly zero energy building | S14: Floors; Gluing; Greenhouse Gases; Heating; Lamination; Life Cycle; Apartment houses; Concrete slabs; Electric power systems; Floors; Gas emissions; Glues; Gluing; Greenhouse gases; Heating; Laminating; Life cycle; Timber; Wooden floors; Comparative assessment; Cross laminated; Electric energy systems; Environmental product declarations; Glue laminated timber; Glued laminated timber (glulam); Life Cycle Assessment (LCA); Residential building; Zero energy buildings | T14: N. Lolli; SINTEF, Building and Infrastructure, Trondheim, Norway; email: nicola.lolli@sintef.no | V14: Taylor and Francis Ltd. | W14: 17480272 | AA14: English | AB14: Wood Mater. Sci. Eng. | AC14: Article | AD14: Final | AF14: Scopus | AG14: 2-s2.0-85070950776
A15: Mirdad M.A.H.; Chui Y.H. | B15: 57190062072; 7004982369 | C15: Load-slip performance of Mass Timber Panel-Concrete (MTPC) composite connection with Self-tapping screws and insulation layer | D15: 2019 | E15: Construction and Building Materials | F15: 213 | I15: 696 | J15: 708 | K15: =scopus[[#This Row],[Page end]]-scopus[[#This Row],[Page start]] -> 12 | L15: 66 | M15: 10.1016/j.conbuildmat.2019.04.117 | N15: https://www.scopus.com/pages/publications/85064437748?origin=resultslist | O15: Department of Civil and Environmental Engineering, Donadeo Innovation Centre for Engineering, University of Alberta, Edmonton, T6G 1H9, Alberta, Canada | P15: Mirdad M.A.H., Department of Civil and Environmental Engineering, Donadeo Innovation Centre for Engineering, University of Alberta, Edmonton, T6G 1H9, Alberta, Canada; Chui Y.H., Department of Civil and Environmental Engineering, Donadeo Innovation Centre for Engineering, University of Alberta, Edmonton, T6G 1H9, Alberta, Canada | Q15: The Mass Timber Panel-Concrete (MTPC) composite floor systems are often encountered in mass timber buildings. Such a floor system consists of a Mass Timber Panel (MTP) connected to a reinforced concrete slab with Self-Tapping Screw (STS) connector and a sound insulation layer in between. In this study three types of MTPs with normal weight concrete, three insulation thicknesses, two screw embedment lengths and two screw angles were tested to characterize connection stiffness and strength. The main goal of this connection test program was to provide preliminary test data to assist in the development of an analytical model to predict connection lateral stiffness and strength considering the insulation layer in the MTPC system. Test results showed that connections with screws at an insertion angle of 30° had a larger stiffness and strength than connections with screws inserted at a 45° angle. Stiffness appears to be more sensitive to the presence of an insulation layer compared to strength. Overall, 35–50% and 55–65% reduction of serviceability stiffness, and 5–15% and 22–34% reduction of strength were noticed for an insulation thickness of 5 mm and 15 mm, respectively. Screws in Cross Laminated Timber (CLT) showed higher strength while screws in Glue Laminated Timber (GLT) showed higher stiffness, but the difference is insignificant in all three MTP products with different failure modes. © 2019 Elsevier Ltd | R15: Insulation layer; Mass timber panel; Self-tapping screw; Timber-concrete composite floor | S15: Concrete slabs; Floors; Laminating; Reinforced concrete; Screws; Software testing; Stiffness; Timber; Wooden buildings; Composite connections; Composite floor systems; Glue laminated timber; Insulation layers; Mass timber panel; Normal weight concrete; Self-tapping screws; Timber-concrete composites; Sound insulation | T15: M.A.H. Mirdad; Department of Civil and Environmental Engineering, Donadeo Innovation Centre for Engineering, University of Alberta, Edmonton, T6G 1H9, Canada; email: mdabdul@ualberta.ca | V15: Elsevier Ltd | W15: 9500618 | Y15: CBUME | AA15: English | AB15: Constr Build Mater | AC15: Article | AD15: Final | AF15: Scopus | AG15: 2-s2.0-85064437748
A16: Jafari M.; Sgambi L. | B16: 60173507600; 6506784463 | C16: Assessing the Environmental Performance of Hybrid Timber-Concrete Systems in High-Rise Building | D16: 2025 | E16: Proceedings of the International Conference of Architectural Science Association | I16: 166 | J16: 175 | K16: =scopus[[#This Row],[Page end]]-scopus[[#This Row],[Page start]] -> 9 | L16: 0 | M16: 10.65388/NUHN4734 | N16: https://www.scopus.com/pages/publications/105034748919?origin=resultslist | O16: Université Catholique de Louvain, Louvain-la-Neuve, Belgium | P16: Jafari M., Université Catholique de Louvain, Louvain-la-Neuve, Belgium; Sgambi L., Université Catholique de Louvain, Louvain-la-Neuve, Belgium | Q16: The construction industry has traditionally relied on reinforced concrete as the primary structural material in high-rise buildings, valued for its strength, durability, and fire resistance. However, its high environmental impact-mainly due to cement production, which contributes approximately 8% of global CO2 emissions-has raised concerns about its sustainability. As global efforts to reduce carbon emissions intensify, alternative construction approaches are gaining traction. Among them, hybrid timber-concrete systems offer a promising solution by combining the carbon-storing benefits of timber with the structural advantages of concrete. This study evaluates the environmental performance of hybrid timber-concrete systems in a 40-storey, 120-meter high-rise tower by comparing five structural typologies that vary in the number of Cross-Laminated Timber (CLT) floor slabs. The reference typology consists of a fully concrete frame with a cast-in-place concrete core, BubbleDeck slabs, and brick walls. The four alternative designs retain the concrete core while progressively replacing concrete slabs with CLT and using CLT for the walls. Structural modelling is conducted using Karamba 3D, while embodied greenhouse gas emissions (EGHGE) are quantified based on Global Warming Potential (GWP) indicators from the ÖKOBAUDAT database and EN 15804+A2 standards. Acoustic and fire performance are also evaluated, ensuring compliance with Belgian fire regulations and NBN EN ISO 16283 standards. The results show that total emissions decrease from 11.3 million to 7.45 million kgCO2e as CLT use increases-a reduction of over 34%. The study confirms the potential of hybrid systems to reduce embodied carbon while maintaining performance and regulatory compliance. © 2025, The Architectural Science Association and The University of Melbourne, Australia. | R16: embodied greenhouse gas emissions; high-rise buildings; Hybrid timber-concrete buildings; life cycle assessment | T16: M. Jafari; Université Catholique de Louvain, Louvain-la-Neuve, Belgium; email: Maryam.jafari@uclouvain.be | U16: Crawford R.H.; Stephan A.; Candido C.; Helal J.; Gobinath P. | V16: Architectural Science Association | W16: 22093850 | X16: 978-176373991-8 | AA16: English | AB16: Proc. Internat. Conf. Architech. Sci. Asso. | AC16: Conference paper | AD16: Final | AE16: All Open Access; Gold Open Access; Green Open Access | AF16: Scopus | AG16: 2-s2.0-105034748919
A17: Chapagain A.; Crovella P. | B17: 59961156800; 57190004292 | C17: Building Sustainable Futures: Evaluating Embodied Carbon Emissions and Biogenic Carbon Storage in a Cross-Laminated Timber Wall and Floor (Honeycomb) Mass Timber Building | D17: 2025 | E17: Sustainability (Switzerland) | F17: 17 | G17: 12 | H17: 5602 | L17: 4 | M17: 10.3390/su17125602 | N17: https://www.scopus.com/pages/publications/105008954389?origin=resultslist | O17: Department of Sustainable Resource Management, State University of New York College of Environmental Science and Forestry (SUNY ESF), 1 Forestry Drive, Syracuse, 13210, NY, United States | P17: Chapagain A., Department of Sustainable Resource Management, State University of New York College of Environmental Science and Forestry (SUNY ESF), 1 Forestry Drive, Syracuse, 13210, NY, United States; Crovella P., Department of Sustainable Resource Management, State University of New York College of Environmental Science and Forestry (SUNY ESF), 1 Forestry Drive, Syracuse, 13210, NY, United States | Q17: The building sector significantly contributes to global energy consumption and carbon emissions, primarily due to the extensive use of carbon-intensive materials such as concrete and steel. Mass timber construction, particularly using cross-laminated timber (CLT), offers a promising low-carbon alternative. This study aims to calculate the embodied carbon emissions and biogenic carbon storage of a CLT-based affordable housing project, 340+ Dixwell in New Haven, Connecticut. This project was designed using a honeycomb structural system, where mass timber floors and roofs are supported by mass timber-bearing walls. The authors are not aware of a prior study that has evaluated the life cycle impacts of honeycomb mass timber construction while considering Timber Use Intensity (TUI). Unlike traditional post-and-beam systems, the honeycomb design uses nearly twice the amount of timber, resulting in higher carbon sequestration. This makes the study significant from a sustainability perspective. This study follows International Standard Organization (ISO) standards 14044, 21930, and 21931 and reports the results for both lifecycle stages A1–A3 and A1–A5. The analysis covers key building components, including the substructure, superstructure, and enclosure, with timber, concrete, metals, glass, and insulation as the materials assessed. Material quantities were extracted using Autodesk Revit®, and the life cycle assessment (LCA) was evaluated using One Click LCA (2015)®. The A1 to A3 stage results of this honeycomb building revealed that, compared to conventional mass timber housing structures such as Adohi Hall and Heartwood, it demonstrates the lowest embodiedf carbon emissions and the highest biogenic carbon storage per square foot. This outcome is largely influenced by its higher Timber Use Intensity (TUI). Similarly, the A1-A5 findings indicate that the embodied carbon emissions of this honeycomb construction are 40% lower than the median value for other multi-family residential buildings, as assessed using the Carbon Leadership Forum (CLF) Embodied Carbon Emissions Benchmark Study of various buildings. Moreover, the biogenic carbon storage per square foot of this building is 60% higher than the average biogenic carbon storage of reference mass timber construction types. © 2025 by the authors. | R17: cross-laminated timber (CLT); honeycomb; life cycle assessment (LCA); Sustainable Construction; Timber Use Intensity (TUI) | S17: Connecticut; New Haven; United States; affordable housing; building construction; carbon emission; carbon storage; construction material; life cycle analysis; standard (regulation); timber | T17: P. Crovella; Department of Sustainable Resource Management, State University of New York College of Environmental Science and Forestry (SUNY ESF), Syracuse, 1 Forestry Drive, 13210, United States; email: plcrovella@esf.edu | V17: Multidisciplinary Digital Publishing Institute (MDPI) | W17: 20711050 | AA17: English | AB17: Sustainability | AC17: Article | AD17: Final | AE17: All Open Access; Gold Open Access | AF17: Scopus | AG17: 2-s2.0-105008954389
A18: Furukawa S.; Iwami R.; Kimura Y. | B18: 55737538800; 58771564400; 37088844100 | C18: Development of an Environmentally Friendly Steel Structural Framework: Evaluation of Bending Stiffness and Yield Bending Moment of Cross-Laminated Timber Slab–H-Shaped Steel Composite Beams for Component Reuse | D18: 2025 | E18: Sustainability (Switzerland) | F18: 17 | G18: 5 | H18: 2073 | L18: 5 | M18: 10.3390/su17052073 | N18: https://www.scopus.com/pages/publications/86000639763?origin=resultslist | O18: Graduate School of Engineering, Osaka Metropolitan University, Osaka, 558-8585, Japan; Graduate School of Engineering, Tohoku University, Sendai, 980-8579, Japan; KEN KEN Co., Ltd., Tokyo, 103-0012, Japan | P18: Furukawa S., Graduate School of Engineering, Osaka Metropolitan University, Osaka, 558-8585, Japan, Graduate School of Engineering, Tohoku University, Sendai, 980-8579, Japan; Iwami R., KEN KEN Co., Ltd., Tokyo, 103-0012, Japan; Kimura Y., Graduate School of Engineering, Tohoku University, Sendai, 980-8579, Japan | Q18: The building and construction sector accounts for nearly 40% of global greenhouse gas emissions, with steel-framed buildings being a significant contributor due to high CO2 emissions during production. To mitigate this issue, integrating Cross-Laminated Timber (CLT) into structural systems has emerged as a sustainable alternative. CLT, known for its carbon sequestration properties, offers an environmentally friendly replacement for reinforced-concrete slabs, particularly when paired with steel structures to enhance material reuse and reduce lifecycle impacts. This study focuses on hybrid systems combining H-shaped steel beams and CLT floor panels connected using high-strength friction bolts. A four-point bending test, simulating a secondary beam, was conducted, demonstrating that the composite effect significantly enhances flexural stiffness and strength. Additionally, a simplified method for evaluating the flexural stiffness and yielding strength of these composite beams, based on material and joint properties, was shown to successfully evaluate the test results. © 2025 by the authors. | R18: bolt friction joint; CLT floor panel; component reuse; steel structures | S18: bending; bolt; building; friction; greenhouse gas; reinforced concrete; replacement; steel structure; stiffness | T18: S. Furukawa; Graduate School of Engineering, Osaka Metropolitan University, Osaka, 558-8585, Japan; email: furukawa-s@omu.ac.jp | V18: Multidisciplinary Digital Publishing Institute (MDPI) | W18: 20711050 | AA18: English | AB18: Sustainability | AC18: Article | AD18: Final | AE18: All Open Access; Gold Open Access | AF18: Scopus | AG18: 2-s2.0-86000639763
